5:return {{["x"] = 0, ["meta"] = {["fields"] = {}, ["inventory"] = {}}, ["y"] = 0, ["param1"] = 13, ["z"] = 0, ["name"] = "default:desert_sandstone"}, {["x"] = 0, ["meta"] = {["fields"] = {}, ["inventory"] = {}}, ["y"] = 0, ["param1"] = 13, ["z"] = 1, ["name"] = "default:desert_sandstone"}, {["x"] = 0, ["meta"] = {["fields"] = {}, ["inventory"] = {}}, ["y"] = 0, ["param1"] = 13, ["z"] = 2, ["name"] = "default:desert_sandstone"}, {["x"] = 0, ["meta"] = {["fields"] = {}, ["inventory"] = {}}, ["y"] = 0, ["param1"] = 13, ["z"] = 3, ["name"] = "default:desert_sandstone"}, {["x"] = 0, ["meta"] = {["fields"] = {}, ["inventory"] = {}}, ["y"] = 0, ["param1"] = 13, ["z"] = 4, ["name"] = "default:desert_sandstone"}, {["x"] = 0, ["meta"] = {["fields"] = {}, ["inventory"] = {}}, ["y"] = 0, ["param1"] = 13, ["z"] = 5, ["name"] = "default:desert_sandstone"}, {["x"] = 0, ["meta"] = {["fields"] = {}, ["inventory"] = {}}, ["y"] = 0, ["param1"] = 13, ["z"] = 6, ["name"] = "default:desert_sandstone"}, {["x"] = 0, ["meta"] = {["fields"] = {}, ["inventory"] = {}}, ["y"] = 0, ["param1"] = 13, ["z"] = 7, ["name"] = "default:desert_sandstone"}, {["x"] = 0, ["meta"] = {["fields"] = {}, ["inventory"] = {}}, ["y"] = 1, ["param1"] = 8, ["z"] = 1, ["name"] = "default:desert_stonebrick"}, {["x"] = 0, ["meta"] = {["fields"] = {}, ["inventory"] = {}}, ["y"] = 1, ["param1"] = 8, ["z"] = 2, ["name"] = "default:desert_stonebrick"}, {["x"] = 0, ["meta"] = {["fields"] = {["infotext"] = "Day night block: ratio=", ["formspec"] = "size[8,2;]field[0.2,0.5;8,1;ratio;Ratio (0...1 or empty);]button_exit[0.1,1.5;8,1;save;Save]"}, ["inventory"] = {}}, ["param2"] = 2, ["y"] = 1, ["param1"] = 16, ["z"] = 3, ["name"] = "epic:daynightratio"}, {["x"] = 0, ["meta"] = {["fields"] = {}, ["inventory"] = {}}, ["y"] = 2, ["param1"] = 8, ["z"] = 0, ["name"] = "default:desert_stonebrick"}, {["x"] = 0, ["meta"] = {["fields"] = {}, ["inventory"] = {}}, ["y"] = 2, ["param1"] = 8, ["z"] = 1, ["name"] = "default:desert_stonebrick"}, {["x"] = 0, ["meta"] = {["fields"] = {["pos"] = "(0,1,0)", ["formspec"] = "size[8,4;]field[0.2,0.5;8,1;topic;Topic;My maze]field[0.2,1.5;8,1;name;Name;Level 1]button_exit[0.1,2.1;4,1;setpos;Set position]button_exit[4.1,2.1;4,1;showpos;Show]button_exit[0.1,3.5;8,1;save;Save]", ["infotext"] = "Savegame block: 'My maze/Level 1'", ["name"] = "Level 1", ["topic"] = "My maze"}, ["inventory"] = {}}, ["param2"] = 2, ["y"] = 2, ["param1"] = 22, ["z"] = 2, ["name"] = "epic:save"}, {["x"] = 0, ["meta"] = {["fields"] = {}, ["inventory"] = {}}, ["y"] = 3, ["param1"] = 8, ["z"] = 0, ["name"] = "default:desert_stonebrick"}, {["x"] = 0, ["meta"] = {["fields"] = {}, ["inventory"] = {}}, ["param2"] = 2, ["y"] = 3, ["param1"] = 31, ["z"] = 1, ["name"] = "epic:check_empty_armor"}, {["x"] = 1, ["meta"] = {["fields"] = {}, ["inventory"] = {}}, ["y"] = 0, ["param1"] = 13, ["z"] = 0, ["name"] = "default:desert_sandstone"}, {["x"] = 1, ["meta"] = {["fields"] = {}, ["inventory"] = {}}, ["y"] = 0, ["param1"] = 13, ["z"] = 1, ["name"] = "default:desert_sandstone"}, {["x"] = 1, ["meta"] = {["fields"] = {}, ["inventory"] = {}}, ["y"] = 0, ["param1"] = 13, ["z"] = 2, ["name"] = "default:desert_sandstone"}, {["x"] = 1, ["meta"] = {["fields"] = {}, ["inventory"] = {}}, ["y"] = 0, ["param1"] = 13, ["z"] = 3, ["name"] = "default:desert_sandstone"}, {["x"] = 1, ["meta"] = {["fields"] = {}, ["inventory"] = {}}, ["y"] = 0, ["param1"] = 13, ["z"] = 4, ["name"] = "default:desert_sandstone"}, {["x"] = 1, ["meta"] = {["fields"] = {}, ["inventory"] = {}}, ["y"] = 0, ["param1"] = 13, ["z"] = 5, ["name"] = "default:desert_sandstone"}, {["x"] = 1, ["meta"] = {["fields"] = {}, ["inventory"] = {}}, ["y"] = 0, ["param1"] = 13, ["z"] = 6, ["name"] = "default:desert_sandstone"}, {["x"] = 1, ["meta"] = {["fields"] = {}, ["inventory"] = {}}, ["y"] = 0, ["param1"] = 13, ["z"] = 7, ["name"] = "default:desert_sandstone"}, {["x"] = 1, ["meta"] = {["fields"] = {}, ["inventory"] = {}}, ["y"] = 1, ["param1"] = 8, ["z"] = 2, ["name"] = "default:desert_stonebrick"}, {["x"] = 1, ["meta"] = {["fields"] = {["infotext"] = "Call block: function=(0,0,0)", ["pos"] = "(0,0,0)", ["formspec"] = "size[8,1;]button_exit[0.1,0.5;4,1;setfn;Set function]button_exit[4.1,0.5;4,1;showpos;Show]"}, ["inventory"] = {}}, ["param2"] = 2, ["y"] = 1, ["param1"] = 6, ["z"] = 3, ["name"] = "epic:call"}, {["x"] = 1, ["meta"] = {["fields"] = {["owner"] = "singleplayer", ["time"] = "600"}, ["inventory"] = {}}, ["y"] = 1, ["param1"] = 249, ["z"] = 6, ["name"] = "epic:epic"}, {["x"] = 1, ["meta"] = {["fields"] = {}, ["inventory"] = {}}, ["y"] = 2, ["param1"] = 8, ["z"] = 1, ["name"] = "default:desert_stonebrick"}, {["x"] = 1, ["meta"] = {["fields"] = {["infotext"] = "Remove item block: pos=(0,0,0)", ["pos"] = "(0,0,0)", ["radius"] = "5", ["formspec"] = "size[8,3;]button_exit[0.1,0.1;4,1;setpos;Set position]button_exit[4.1,0.1;4,1;showpos;Show]field[0.2,1.5;8,1;radius;Radius;5]button_exit[0.1,2.5;8,1;save;Save]"}, ["inventory"] = {}}, ["param2"] = 2, ["y"] = 2, ["param1"] = 18, ["z"] = 2, ["name"] = "epic:removeitem"}, {["x"] = 1, ["meta"] = {["fields"] = {}, ["inventory"] = {}}, ["y"] = 3, ["param1"] = 8, ["z"] = 0, ["name"] = "default:desert_stonebrick"}, {["x"] = 1, ["meta"] = {["fields"] = {["infotext"] = "Unlock block: pos=(-124,11,-32)", ["pos"] = "(-124,11,-32)", ["formspec"] = "size[8,1;]button_exit[0.1,0.5;4,1;setpos;Set position]button_exit[4.1,0.5;4,1;showpos;Show]"}, ["inventory"] = {}}, ["param2"] = 2, ["y"] = 3, ["param1"] = 20, ["z"] = 1, ["name"] = "epic:unlock"}, {["x"] = 2, ["meta"] = {["fields"] = {}, ["inventory"] = {}}, ["y"] = 0, ["param1"] = 13, ["z"] = 0, ["name"] = "default:desert_sandstone"}, {["x"] = 2, ["meta"] = {["fields"] = {}, ["inventory"] = {}}, ["y"] = 0, ["param1"] = 13, ["z"] = 1, ["name"] = "default:desert_sandstone"}, {["x"] = 2, ["meta"] = {["fields"] = {}, ["inventory"] = {}}, ["y"] = 0, ["param1"] = 13, ["z"] = 2, ["name"] = "default:desert_sandstone"}, {["x"] = 2, ["meta"] = {["fields"] = {}, ["inventory"] = {}}, ["y"] = 0, ["param1"] = 13, ["z"] = 3, ["name"] = "default:desert_sandstone"}, {["x"] = 2, ["meta"] = {["fields"] = {}, ["inventory"] = {}}, ["y"] = 0, ["param1"] = 13, ["z"] = 4, ["name"] = "default:desert_sandstone"}, {["x"] = 2, ["meta"] = {["fields"] = {}, ["inventory"] = {}}, ["y"] = 0, ["param1"] = 13, ["z"] = 5, ["name"] = "default:desert_sandstone"}, {["x"] = 2, ["meta"] = {["fields"] = {}, ["inventory"] = {}}, ["y"] = 0, ["param1"] = 13, ["z"] = 6, ["name"] = "default:desert_sandstone"}, {["x"] = 2, ["meta"] = {["fields"] = {}, ["inventory"] = {}}, ["y"] = 0, ["param1"] = 13, ["z"] = 7, ["name"] = "default:desert_sandstone"}, {["x"] = 2, ["meta"] = {["fields"] = {}, ["inventory"] = {}}, ["y"] = 1, ["param1"] = 8, ["z"] = 2, ["name"] = "default:desert_stonebrick"}, {["x"] = 2, ["meta"] = {["fields"] = {["infotext"] = "Add item block: pos=(0,0,0)", ["pos"] = "(0,0,0)", ["formspec"] = "size[8,7;]button_exit[0.1,0.5;4,1;setpos;Set position]button_exit[4.1,0.5;4,1;showpos;Show]label[0,1.5;Item]list[context;main;4,1.5;1,1;]list[current_player;main;0,3;8,4;]listring[]"}, ["inventory"] = {["main"] = {""}}}, ["param2"] = 2, ["y"] = 1, ["param1"] = 17, ["z"] = 3, ["name"] = "epic:additem"}, {["x"] = 2, ["meta"] = {["fields"] = {}, ["inventory"] = {}}, ["y"] = 2, ["param1"] = 8, ["z"] = 1, ["name"] = "default:desert_stonebrick"}, {["x"] = 2, ["meta"] = {["fields"] = {}, ["inventory"] = {}}, ["param2"] = 2, ["y"] = 2, ["param1"] = 250, ["z"] = 2, ["name"] = "epic:nop"}, {["x"] = 2, ["meta"] = {["fields"] = {}, ["inventory"] = {}}, ["y"] = 3, ["param1"] = 8, ["z"] = 0, ["name"] = "default:desert_stonebrick"}, {["x"] = 2, ["meta"] = {["fields"] = {["infotext"] = "Teleport relative block: source=(0,0,0) target=(0,0,0)", ["target"] = "(0,0,0)", ["source"] = "(0,0,0)", ["formspec"] = "size[8,2;]label[0,0.5;Source]label[2,0.5;(0,0,0)]button_exit[4,0.5;2,1;setsource;Set]button_exit[6,0.5;2,1;showsource;Show]label[0,1.5;Target]label[2,1.5;(0,0,0)]button_exit[4,1.5;2,1;settarget;Set]button_exit[6,1.5;2,1;showtarget;Show]"}, ["inventory"] = {}}, ["param2"] = 2, ["y"] = 3, ["param1"] = 2, ["z"] = 1, ["name"] = "epic:teleport_relative"}, {["x"] = 3, ["meta"] = {["fields"] = {}, ["inventory"] = {}}, ["y"] = 0, ["param1"] = 13, ["z"] = 0, ["name"] = "default:desert_sandstone"}, {["x"] = 3, ["meta"] = {["fields"] = {}, ["inventory"] = {}}, ["y"] = 0, ["param1"] = 13, ["z"] = 1, ["name"] = "default:desert_sandstone"}, {["x"] = 3, ["meta"] = {["fields"] = {}, ["inventory"] = {}}, ["y"] = 0, ["param1"] = 13, ["z"] = 2, ["name"] = "default:desert_sandstone"}, {["x"] = 3, ["meta"] = {["fields"] = {}, ["inventory"] = {}}, ["y"] = 0, ["param1"] = 13, ["z"] = 3, ["name"] = "default:desert_sandstone"}, {["x"] = 3, ["meta"] = {["fields"] = {}, ["inventory"] = {}}, ["y"] = 0, ["param1"] = 13, ["z"] = 4, ["name"] = "default:desert_sandstone"}, {["x"] = 3, ["meta"] = {["fields"] = {}, ["inventory"] = {}}, ["y"] = 0, ["param1"] = 13, ["z"] = 5, ["name"] = "default:desert_sandstone"}, {["x"] = 3, ["meta"] = {["fields"] = {}, ["inventory"] = {}}, ["y"] = 0, ["param1"] = 13, ["z"] = 6, ["name"] = "default:desert_sandstone"}, {["x"] = 3, ["meta"] = {["fields"] = {}, ["inventory"] = {}}, ["y"] = 0, ["param1"] = 13, ["z"] = 7, ["name"] = "default:desert_sandstone"}, {["x"] = 3, ["meta"] = {["fields"] = {}, ["inventory"] = {}}, ["y"] = 1, ["param1"] = 8, ["z"] = 2, ["name"] = "default:desert_stonebrick"}, {["x"] = 3, ["meta"] = {["fields"] = {}, ["inventory"] = {}}, ["param2"] = 2, ["y"] = 1, ["param1"] = 9, ["z"] = 3, ["name"] = "epic:branch"}, {["x"] = 3, ["meta"] = {["fields"] = {}, ["inventory"] = {}}, ["y"] = 2, ["param1"] = 8, ["z"] = 1, ["name"] = "default:desert_stonebrick"}, {["x"] = 3, ["meta"] = {["fields"] = {["infotext"] = "Chat block: 'Hello world'", ["formspec"] = "size[8,2;]field[0.2,0.5;8,1;text;Text;Hello world]button_exit[0.1,1.5;8,1;save;Save]", ["text"] = "Hello world"}, ["inventory"] = {}}, ["param2"] = 2, ["y"] = 2, ["param1"] = 254, ["z"] = 2, ["name"] = "epic:message"}, {["x"] = 3, ["meta"] = {["fields"] = {}, ["inventory"] = {}}, ["y"] = 3, ["param1"] = 8, ["z"] = 0, ["name"] = "default:desert_stonebrick"}, {["x"] = 3, ["meta"] = {["fields"] = {["infotext"] = "Teleport block: pos=(0,0,0)", ["pos"] = "(0,0,0)", ["formspec"] = "size[8,1;]button_exit[0.1,0.5;4,1;setpos;Set position]button_exit[4.1,0.5;4,1;showpos;Show]"}, ["inventory"] = {}}, ["param2"] = 2, ["y"] = 3, ["param1"] = 1, ["z"] = 1, ["name"] = "epic:teleport"}, {["x"] = 4, ["meta"] = {["fields"] = {}, ["inventory"] = {}}, ["y"] = 0, ["param1"] = 13, ["z"] = 0, ["name"] = "default:desert_sandstone"}, {["x"] = 4, ["meta"] = {["fields"] = {}, ["inventory"] = {}}, ["y"] = 0, ["param1"] = 13, ["z"] = 1, ["name"] = "default:desert_sandstone"}, {["x"] = 4, ["meta"] = {["fields"] = {}, ["inventory"] = {}}, ["y"] = 0, ["param1"] = 13, ["z"] = 2, ["name"] = "default:desert_sandstone"}, {["x"] = 4, ["meta"] = {["fields"] = {}, ["inventory"] = {}}, ["y"] = 0, ["param1"] = 13, ["z"] = 3, ["name"] = "default:desert_sandstone"}, {["x"] = 4, ["meta"] = {["fields"] = {}, ["inventory"] = {}}, ["y"] = 0, ["param1"] = 13, ["z"] = 4, ["name"] = "default:desert_sandstone"}, {["x"] = 4, ["meta"] = {["fields"] = {}, ["inventory"] = {}}, ["y"] = 0, ["param1"] = 13, ["z"] = 5, ["name"] = "default:desert_sandstone"}, {["x"] = 4, ["meta"] = {["fields"] = {}, ["inventory"] = {}}, ["y"] = 0, ["param1"] = 13, ["z"] = 6, ["name"] = "default:desert_sandstone"}, {["x"] = 4, ["meta"] = {["fields"] = {}, ["inventory"] = {}}, ["y"] = 0, ["param1"] = 13, ["z"] = 7, ["name"] = "default:desert_sandstone"}, {["x"] = 4, ["meta"] = {["fields"] = {}, ["inventory"] = {}}, ["y"] = 1, ["param1"] = 8, ["z"] = 2, ["name"] = "default:desert_stonebrick"}, {["x"] = 4, ["meta"] = {["fields"] = {}, ["inventory"] = {}}, ["y"] = 1, ["param1"] = 8, ["z"] = 3, ["name"] = "default:desert_stonebrick"}, {["x"] = 4, ["meta"] = {["fields"] = {["infotext"] = "Load game", ["topic"] = "My maze"}, ["inventory"] = {}}, ["param2"] = 1, ["y"] = 1, ["param1"] = 23, ["z"] = 4, ["name"] = "epic:load"}, {["x"] = 4, ["meta"] = {["fields"] = {["infotext"] = "on_exit callback block: function=(0,0,0)", ["pos"] = "(0,0,0)", ["formspec"] = "size[8,1;]button_exit[0.1,0.5;4,1;setfn;Set function]button_exit[4.1,0.5;4,1;showpos;Show]"}, ["inventory"] = {}}, ["param2"] = 1, ["y"] = 1, ["param1"] = 251, ["z"] = 5, ["name"] = "epic:on_exit"}, {["x"] = 4, ["meta"] = {["fields"] = {["infotext"] = "on_abort callback block: function=(0,0,0)", ["pos"] = "(0,0,0)", ["formspec"] = "size[8,1;]button_exit[0.1,0.5;4,1;setfn;Set function]button_exit[4.1,0.5;4,1;showpos;Show]"}, ["inventory"] = {}}, ["param2"] = 1, ["y"] = 1, ["param1"] = 252, ["z"] = 6, ["name"] = "epic:on_abort"}, {["x"] = 4, ["meta"] = {["fields"] = {["formspec"] = "size[8,1;]button_exit[0.1,0.2;8,1;execute;Execute]"}, ["inventory"] = {}}, ["param2"] = 1, ["y"] = 1, ["param1"] = 253, ["z"] = 7, ["name"] = "epic:function"}, {["x"] = 4, ["meta"] = {["fields"] = {}, ["inventory"] = {}}, ["y"] = 2, ["param1"] = 8, ["z"] = 1, ["name"] = "default:desert_stonebrick"}, {["x"] = 4, ["meta"] = {["fields"] = {["infotext"] = "Mesecons emit block: 1 seconds", ["formspec"] = "size[8,2;]field[0.2,0.5;8,1;delay;Delay (seconds);1]button_exit[0.1,1.5;8,1;save;Save]", ["delay"] = "1"}, ["inventory"] = {}}, ["param2"] = 2, ["y"] = 2, ["param1"] = 32, ["z"] = 2, ["name"] = "epic:mesecon_emit"}, {["x"] = 4, ["meta"] = {["fields"] = {}, ["inventory"] = {}}, ["y"] = 3, ["param1"] = 8, ["z"] = 0, ["name"] = "default:desert_stonebrick"}, {["x"] = 4, ["meta"] = {["fields"] = {["infotext"] = "Visits: 0 Last player: '''", ["formspec"] = "size[8,2;]label[0,0.5;Visits: 0]button_exit[0.1,1.5;8,1;reset;Reset]", ["counter"] = "0"}, ["inventory"] = {}}, ["param2"] = 2, ["y"] = 3, ["param1"] = 7, ["z"] = 1, ["name"] = "epic:stats"}, {["x"] = 4, ["meta"] = {["fields"] = {["pos"] = "(0,0,0)", ["formspec"] = "size[8,4;]field[0.2,0.5;8,1;radius;Radius;3]field[0.2,1.5;8,1;name;Name;Waypoint]button_exit[0.1,2.5;4,1;setpos;Set]button_exit[4.1,2.5;4,1;showpos;Show]button_exit[0.1,3.5;8,1;save;Save]", ["infotext"] = "Inverse waypoint block: pos=(0,0,0), radius=3", ["radius"] = "3", ["name"] = "Waypoint"}, ["inventory"] = {}}, ["param2"] = 2, ["y"] = 4, ["z"] = 0, ["name"] = "epic:waypoint_inverse"}, {["x"] = 5, ["meta"] = {["fields"] = {}, ["inventory"] = {}}, ["y"] = 0, ["param1"] = 13, ["z"] = 0, ["name"] = "default:desert_sandstone"}, {["x"] = 5, ["meta"] = {["fields"] = {}, ["inventory"] = {}}, ["y"] = 0, ["param1"] = 13, ["z"] = 1, ["name"] = "default:desert_sandstone"}, {["x"] = 5, ["meta"] = {["fields"] = {}, ["inventory"] = {}}, ["y"] = 0, ["param1"] = 13, ["z"] = 2, ["name"] = "default:desert_sandstone"}, {["x"] = 5, ["meta"] = {["fields"] = {}, ["inventory"] = {}}, ["y"] = 0, ["param1"] = 13, ["z"] = 3, ["name"] = "default:desert_sandstone"}, {["x"] = 5, ["meta"] = {["fields"] = {}, ["inventory"] = {}}, ["y"] = 0, ["param1"] = 13, ["z"] = 4, ["name"] = "default:desert_sandstone"}, {["x"] = 5, ["meta"] = {["fields"] = {}, ["inventory"] = {}}, ["y"] = 0, ["param1"] = 13, ["z"] = 5, ["name"] = "default:desert_sandstone"}, {["x"] = 5, ["meta"] = {["fields"] = {}, ["inventory"] = {}}, ["y"] = 0, ["param1"] = 13, ["z"] = 6, ["name"] = "default:desert_sandstone"}, {["x"] = 5, ["meta"] = {["fields"] = {}, ["inventory"] = {}}, ["y"] = 0, ["param1"] = 13, ["z"] = 7, ["name"] = "default:desert_sandstone"}, {["x"] = 5, ["meta"] = {["fields"] = {}, ["inventory"] = {}}, ["y"] = 1, ["param1"] = 8, ["z"] = 2, ["name"] = "default:desert_stonebrick"}, {["x"] = 5, ["meta"] = {["fields"] = {}, ["inventory"] = {}}, ["y"] = 1, ["param1"] = 8, ["z"] = 3, ["name"] = "default:desert_stonebrick"}, {["x"] = 5, ["meta"] = {["fields"] = {}, ["inventory"] = {}}, ["y"] = 1, ["param1"] = 8, ["z"] = 4, ["name"] = "default:desert_stonebrick"}, {["x"] = 5, ["meta"] = {["fields"] = {}, ["inventory"] = {}}, ["y"] = 1, ["param1"] = 8, ["z"] = 5, ["name"] = "default:desert_stonebrick"}, {["x"] = 5, ["meta"] = {["fields"] = {}, ["inventory"] = {}}, ["y"] = 1, ["param1"] = 8, ["z"] = 6, ["name"] = "default:desert_stonebrick"}, {["x"] = 5, ["meta"] = {["fields"] = {}, ["inventory"] = {}}, ["y"] = 1, ["param1"] = 8, ["z"] = 7, ["name"] = "default:desert_stonebrick"}, {["x"] = 5, ["meta"] = {["fields"] = {}, ["inventory"] = {}}, ["y"] = 2, ["param1"] = 8, ["z"] = 1, ["name"] = "default:desert_stonebrick"}, {["x"] = 5, ["meta"] = {["fields"] = {}, ["inventory"] = {}}, ["y"] = 2, ["param1"] = 8, ["z"] = 2, ["name"] = "default:desert_stonebrick"}, {["x"] = 5, ["meta"] = {["fields"] = {["infotext"] = "Filter inventory", ["formspec"] = "size[8,7;]list[context;main;0,0.5;8,1;]list[current_player;main;0,3;8,4;]listring[]"}, ["inventory"] = {["main"] = {"", "", "", "", "", "", "", ""}}}, ["param2"] = 1, ["y"] = 2, ["param1"] = 29, ["z"] = 3, ["name"] = "epic:filter_inv"}, {["x"] = 5, ["meta"] = {["fields"] = {["infotext"] = "Fill chest @ (0,0,0)", ["pos"] = "(0,0,0)", ["formspec"] = "size[8,11;]list[context;main;0,0.5;8,4;]button_exit[0.1,5.5;4,1;setfn;Set target chest]button_exit[4.1,5.5;4,1;showpos;Show]list[current_player;main;0,7;8,4;]listring[]"}, ["inventory"] = {["main"] = {"", "", "", "", "", "", "", "", "", "", "", "", "", "", "", "", "", "", "", "", "", "", "", "", "", "", "", "", "", "", "", ""}}}, ["param2"] = 1, ["y"] = 2, ["param1"] = 25, ["z"] = 4, ["name"] = "epic:fill_chest"}, {["x"] = 5, ["meta"] = {["fields"] = {}, ["inventory"] = {}}, ["param2"] = 1, ["y"] = 2, ["param1"] = 34, ["z"] = 5, ["name"] = "epic:digiline_emit"}, {["x"] = 5, ["meta"] = {["fields"] = {["owner"] = "singleplayer", ["cmd"] = "status", ["infotext"] = "Command block: 'status'", ["formspec"] = "size[8,2;]field[0.2,0.5;8,1;cmd;Command (use @player and @owner);status]button_exit[0.1,1.5;8,1;save;Save]"}, ["inventory"] = {}}, ["param2"] = 1, ["y"] = 2, ["param1"] = 3, ["z"] = 6, ["name"] = "epic:command"}, {["x"] = 5, ["meta"] = {["fields"] = {["infotext"] = "Deduct from inventory", ["formspec"] = "size[8,7;]list[context;main;0,0.5;8,1;]list[current_player;main;0,3;8,4;]listring[]"}, ["inventory"] = {["main"] = {"", "", "", "", "", "", "", ""}}}, ["param2"] = 1, ["y"] = 2, ["param1"] = 28, ["z"] = 7, ["name"] = "epic:deduct_inv"}, {["x"] = 5, ["meta"] = {["fields"] = {}, ["inventory"] = {}}, ["y"] = 3, ["param1"] = 8, ["z"] = 0, ["name"] = "default:desert_stonebrick"}, {["x"] = 5, ["meta"] = {["fields"] = {["infotext"] = "Stash inventory", ["formspec"] = "size[8,7;]list[context;main;0,0.5;8,1;]list[current_player;main;0,3;8,4;]listring[]"}, ["inventory"] = {["main"] = {"", "", "", "", "", "", "", ""}}}, ["param2"] = 2, ["y"] = 3, ["param1"] = 26, ["z"] = 1, ["name"] = "epic:stash_inv"}, {["x"] = 5, ["meta"] = {["fields"] = {["pos"] = "(0,0,0)", ["formspec"] = "size[8,4;]field[0.2,0.5;8,1;radius;Radius;3]field[0.2,1.5;8,1;name;Name;Waypoint]button_exit[0.1,2.5;4,1;setpos;Set]button_exit[4.1,2.5;4,1;showpos;Show]button_exit[0.1,3.5;8,1;save;Save]", ["infotext"] = "Waypoint block: pos=(0,0,0), radius=3", ["radius"] = "3", ["name"] = "Waypoint"}, ["inventory"] = {}}, ["param2"] = 2, ["y"] = 4, ["param1"] = 255, ["z"] = 0, ["name"] = "epic:waypoint"}, {["x"] = 6, ["meta"] = {["fields"] = {}, ["inventory"] = {}}, ["y"] = 0, ["param1"] = 13, ["z"] = 0, ["name"] = "default:desert_sandstone"}, {["x"] = 6, ["meta"] = {["fields"] = {}, ["inventory"] = {}}, ["y"] = 0, ["param1"] = 13, ["z"] = 1, ["name"] = "default:desert_sandstone"}, {["x"] = 6, ["meta"] = {["fields"] = {}, ["inventory"] = {}}, ["y"] = 0, ["param1"] = 13, ["z"] = 2, ["name"] = "default:desert_sandstone"}, {["x"] = 6, ["meta"] = {["fields"] = {}, ["inventory"] = {}}, ["y"] = 0, ["param1"] = 13, ["z"] = 3, ["name"] = "default:desert_sandstone"}, {["x"] = 6, ["meta"] = {["fields"] = {}, ["inventory"] = {}}, ["y"] = 0, ["param1"] = 13, ["z"] = 4, ["name"] = "default:desert_sandstone"}, {["x"] = 6, ["meta"] = {["fields"] = {}, ["inventory"] = {}}, ["y"] = 0, ["param1"] = 13, ["z"] = 5, ["name"] = "default:desert_sandstone"}, {["x"] = 6, ["meta"] = {["fields"] = {}, ["inventory"] = {}}, ["y"] = 0, ["param1"] = 13, ["z"] = 6, ["name"] = "default:desert_sandstone"}, {["x"] = 6, ["meta"] = {["fields"] = {}, ["inventory"] = {}}, ["y"] = 0, ["param1"] = 13, ["z"] = 7, ["name"] = "default:desert_sandstone"}, {["x"] = 6, ["meta"] = {["fields"] = {}, ["inventory"] = {}}, ["y"] = 2, ["param1"] = 8, ["z"] = 1, ["name"] = "default:desert_stonebrick"}, {["x"] = 6, ["meta"] = {["fields"] = {}, ["inventory"] = {}}, ["y"] = 2, ["param1"] = 8, ["z"] = 2, ["name"] = "default:desert_stonebrick"}, {["x"] = 6, ["meta"] = {["fields"] = {}, ["inventory"] = {}}, ["y"] = 2, ["param1"] = 8, ["z"] = 3, ["name"] = "default:desert_stonebrick"}, {["x"] = 6, ["meta"] = {["fields"] = {}, ["inventory"] = {}}, ["y"] = 2, ["param1"] = 8, ["z"] = 4, ["name"] = "default:desert_stonebrick"}, {["x"] = 6, ["meta"] = {["fields"] = {}, ["inventory"] = {}}, ["y"] = 2, ["param1"] = 8, ["z"] = 5, ["name"] = "default:desert_stonebrick"}, {["x"] = 6, ["meta"] = {["fields"] = {}, ["inventory"] = {}}, ["y"] = 2, ["param1"] = 8, ["z"] = 6, ["name"] = "default:desert_stonebrick"}, {["x"] = 6, ["meta"] = {["fields"] = {}, ["inventory"] = {}}, ["y"] = 2, ["param1"] = 8, ["z"] = 7, ["name"] = "default:desert_stonebrick"}, {["x"] = 6, ["meta"] = {["fields"] = {}, ["inventory"] = {}}, ["y"] = 3, ["param1"] = 8, ["z"] = 0, ["name"] = "default:desert_stonebrick"}, {["x"] = 6, ["meta"] = {["fields"] = {}, ["inventory"] = {}}, ["y"] = 3, ["param1"] = 8, ["z"] = 1, ["name"] = "default:desert_stonebrick"}, {["x"] = 6, ["meta"] = {["fields"] = {["infotext"] = "Settimeout block: 300 seconds", ["timeout"] = "300", ["formspec"] = "size[8,2;]field[0.2,0.5;8,1;timeout;Timeout (seconds);300]button_exit[0.1,1.5;8,1;save;Save]"}, ["inventory"] = {}}, ["param2"] = 1, ["y"] = 3, ["param1"] = 21, ["z"] = 2, ["name"] = "epic:settimeout"}, {["x"] = 6, ["meta"] = {["fields"] = {["owner"] = "singleplayer", ["pos"] = "(0,0,0)", ["infotext"] = "Set node block: pos=(0,0,0)", ["formspec"] = "size[8,7;]button_exit[0.1,0.5;4,1;setpos;Set position]button_exit[4.1,0.5;4,1;showpos;Show]label[0,1.5;Item]list[context;main;4,1.5;1,1;]list[current_player;main;0,3;8,4;]listring[]"}, ["inventory"] = {["main"] = {""}}}, ["param2"] = 1, ["y"] = 3, ["param1"] = 12, ["z"] = 3, ["name"] = "epic:setnode"}, {["x"] = 6, ["meta"] = {["fields"] = {["thickness"] = "16", ["speedy"] = "2", ["formspec"] = "size[8,6;]field[0.2,0.5;8,1;thickness;Thickness;${thickness}]field[0.2,1.5;8,1;density;Density;${density}]field[0.2,2.5;8,1;height;Height;${height}]field[0.2,3.5;2,1;red;Red;${red}]field[2.2,3.5;2,1;green;Green;${green}]field[4.2,3.5;2,1;blue;Blue;${blue}]field[6.2,3.5;2,1;alpha;Alpha;${alpha}]field[0.2,4.5;4,1;speedx;X-Speed;${speedx}]field[4.2,4.5;4,1;speedx;Y-Speed;${speedy}]button_exit[0.1,5.5;8,1;save;Save]", ["red"] = "243", ["density"] = "0.4", ["alpha"] = "229", ["green"] = "214", ["infotext"] = "Set clouds block", ["speedx"] = "1", ["height"] = "120", ["blue"] = "255"}, ["inventory"] = {}}, ["param2"] = 1, ["y"] = 3, ["param1"] = 14, ["z"] = 4, ["name"] = "epic:setclouds"}, {["x"] = 6, ["meta"] = {["fields"] = {["infotext"] = "Set param2: pos=(0,0,0) param2=0", ["pos"] = "(0,0,0)", ["param2"] = "0", ["formspec"] = "size[8,3;]button_exit[0.1,0.1;4,1;setpos;Set position]button_exit[4.1,0.1;4,1;showpos;Show]field[0.2,1.5;8,1;param2;Param2;0]button_exit[0.1,2.5;8,1;save;Save]"}, ["inventory"] = {}}, ["param2"] = 1, ["y"] = 3, ["param1"] = 13, ["z"] = 5, ["name"] = "epic:set_param2"}, {["x"] = 6, ["meta"] = {["fields"] = {["infotext"] = "Set-gravity block: '9.81'", ["formspec"] = "size[8,2;]field[0.2,0.5;8,1;gravity;Gravity-multiplier;9.81]button_exit[0.1,1.5;8,1;save;Save]", ["gravity"] = "9.81"}, ["inventory"] = {}}, ["param2"] = 1, ["y"] = 3, ["param1"] = 15, ["z"] = 6, ["name"] = "epic:set_gravity"}, {["x"] = 6, ["meta"] = {["fields"] = {["infotext"] = "Send mapblock block: pos=(0,0,0)", ["pos"] = "(0,0,0)", ["formspec"] = "size[8,1;]button_exit[0.1,0.5;4,1;setpos;Set position]button_exit[4.1,0.5;4,1;showpos;Show]"}, ["inventory"] = {}}, ["param2"] = 1, ["y"] = 3, ["param1"] = 11, ["z"] = 7, ["name"] = "epic:send_mapblock"}, {["x"] = 6, ["meta"] = {["fields"] = {["four-star"] = "0", ["two-star"] = "0", ["counter"] = "0", ["formspec"] = "size[8,8;]label[0,0.5;Visits:  0, Rating: nan]label[0,1.5;1-Star:  0]label[0,2.5;2-Star:  0]label[0,3.5;3-Star:  0]label[0,4.5;4-Star:  0]label[0,5.5;5-Star:  0]button_exit[0.1,6.5;8,1;reset;Reset]", ["no-review"] = "0", ["one-star"] = "0", ["infotext"] = "Visits: 0 Last player: '''", ["three-star"] = "0", ["five-star"] = "0", ["rating"] = "nan"}, ["inventory"] = {}}, ["param2"] = 2, ["y"] = 4, ["param1"] = 8, ["z"] = 0, ["name"] = "epic:review"}, {["x"] = 7, ["meta"] = {["fields"] = {}, ["inventory"] = {}}, ["y"] = 0, ["param1"] = 13, ["z"] = 0, ["name"] = "default:desert_sandstone"}, {["x"] = 7, ["meta"] = {["fields"] = {}, ["inventory"] = {}}, ["y"] = 0, ["param1"] = 13, ["z"] = 1, ["name"] = "default:desert_sandstone"}, {["x"] = 7, ["meta"] = {["fields"] = {}, ["inventory"] = {}}, ["y"] = 0, ["param1"] = 13, ["z"] = 2, ["name"] = "default:desert_sandstone"}, {["x"] = 7, ["meta"] = {["fields"] = {}, ["inventory"] = {}}, ["y"] = 0, ["param1"] = 13, ["z"] = 3, ["name"] = "default:desert_sandstone"}, {["x"] = 7, ["meta"] = {["fields"] = {}, ["inventory"] = {}}, ["y"] = 0, ["param1"] = 13, ["z"] = 4, ["name"] = "default:desert_sandstone"}, {["x"] = 7, ["meta"] = {["fields"] = {}, ["inventory"] = {}}, ["y"] = 0, ["param1"] = 13, ["z"] = 5, ["name"] = "default:desert_sandstone"}, {["x"] = 7, ["meta"] = {["fields"] = {}, ["inventory"] = {}}, ["y"] = 0, ["param1"] = 13, ["z"] = 6, ["name"] = "default:desert_sandstone"}, {["x"] = 7, ["meta"] = {["fields"] = {}, ["inventory"] = {}}, ["y"] = 0, ["param1"] = 13, ["z"] = 7, ["name"] = "default:desert_sandstone"}, {["x"] = 7, ["meta"] = {["fields"] = {}, ["inventory"] = {}}, ["y"] = 3, ["param1"] = 8, ["z"] = 0, ["name"] = "default:desert_stonebrick"}, {["x"] = 7, ["meta"] = {["fields"] = {}, ["inventory"] = {}}, ["y"] = 3, ["param1"] = 8, ["z"] = 1, ["name"] = "default:desert_stonebrick"}, {["x"] = 7, ["meta"] = {["fields"] = {}, ["inventory"] = {}}, ["y"] = 3, ["param1"] = 8, ["z"] = 2, ["name"] = "default:desert_stonebrick"}, {["x"] = 7, ["meta"] = {["fields"] = {}, ["inventory"] = {}}, ["y"] = 3, ["param1"] = 8, ["z"] = 3, ["name"] = "default:desert_stonebrick"}, {["x"] = 7, ["meta"] = {["fields"] = {}, ["inventory"] = {}}, ["y"] = 3, ["param1"] = 8, ["z"] = 4, ["name"] = "default:desert_stonebrick"}, {["x"] = 7, ["meta"] = {["fields"] = {}, ["inventory"] = {}}, ["y"] = 3, ["param1"] = 8, ["z"] = 5, ["name"] = "default:desert_stonebrick"}, {["x"] = 7, ["meta"] = {["fields"] = {}, ["inventory"] = {}}, ["y"] = 3, ["param1"] = 8, ["z"] = 6, ["name"] = "default:desert_stonebrick"}, {["x"] = 7, ["meta"] = {["fields"] = {}, ["inventory"] = {}}, ["y"] = 3, ["param1"] = 8, ["z"] = 7, ["name"] = "default:desert_stonebrick"}, {["x"] = 7, ["meta"] = {["fields"] = {}, ["inventory"] = {}}, ["y"] = 4, ["param1"] = 8, ["z"] = 0, ["name"] = "default:desert_stonebrick"}, {["x"] = 7, ["meta"] = {["fields"] = {["infotext"] = "random block, chance: 1/10", ["formspec"] = "size[8,2;]field[0.2,0.5;8,1;chance;Chance (1/x);10]button_exit[0.1,1.5;8,1;save;Save]", ["chance"] = "10"}, ["inventory"] = {}}, ["param2"] = 1, ["y"] = 4, ["param1"] = 24, ["z"] = 1, ["name"] = "epic:random"}, {["x"] = 7, ["meta"] = {["fields"] = {["infotext"] = "Mesecon check block: pos=(0,0,0)", ["pos"] = "(0,0,0)", ["formspec"] = "size[8,1;]button_exit[0.1,0.5;4,1;setpos;Set]button_exit[4.1,0.5;4,1;showpos;Show]"}, ["inventory"] = {}}, ["param2"] = 1, ["y"] = 4, ["param1"] = 33, ["z"] = 2, ["name"] = "epic:mesecon_check"}, {["x"] = 7, ["meta"] = {["fields"] = {["lock"] = "0"}, ["inventory"] = {}}, ["param2"] = 1, ["y"] = 4, ["param1"] = 19, ["z"] = 3, ["name"] = "epic:lock"}, {["x"] = 7, ["meta"] = {["fields"] = {["infotext"] = "Kill count block: 5 kills", ["kills"] = "5", ["formspec"] = "size[8,2;]field[0.2,0.5;8,1;kills;Kills;5]button_exit[0.1,1.5;8,1;save;Save]"}, ["inventory"] = {}}, ["param2"] = 1, ["y"] = 4, ["param1"] = 10, ["z"] = 4, ["name"] = "epic:kill_count"}, {["x"] = 7, ["meta"] = {["fields"] = {["infotext"] = "Dialogue block: 'Example text'", ["formspec"] = "size[8,2;]field[0.2,0.5;8,1;text;Text;Example text]button_exit[0.1,1.5;8,1;save;Save]", ["text"] = "Example text"}, ["inventory"] = {}}, ["param2"] = 1, ["y"] = 4, ["param1"] = 5, ["z"] = 5, ["name"] = "epic:dialogue"}, {["x"] = 7, ["meta"] = {["fields"] = {["infotext"] = "Delay block: 5 seconds", ["formspec"] = "size[8,2;]field[0.2,0.5;8,1;delay;Delay (seconds);5]button_exit[0.1,1.5;8,1;save;Save]", ["delay"] = "5"}, ["inventory"] = {}}, ["param2"] = 1, ["y"] = 4, ["param1"] = 4, ["z"] = 6, ["name"] = "epic:delay"}, {["x"] = 7, ["meta"] = {["fields"] = {}, ["inventory"] = {}}, ["param2"] = 1, ["y"] = 4, ["param1"] = 30, ["z"] = 7, ["name"] = "epic:check_empty_inv"}}